Programm started at: 2025-07-14 01:27:06

Running in version 1.2[2025-07-14 02:40:08]
Error 1 at reading or storing sensor data.
	'I2C read failed'

	Traceback (most recent call last):
  File "/home/raspi/CO2_Project/main.py", line 211, in <module>
    g_co2_sensor.read_all()
  File "/home/raspi/CO2_Project/ccs811LIBRARY.py", line 191, in read_all
    if self.data_available():
       ^^^^^^^^^^^^^^^^^^^^^
  File "/home/raspi/CO2_Project/ccs811LIBRARY.py", line 172, in data_available
    value = self.pi.i2c_read_byte_data(self.device, CSS811_STATUS)
            ^^^^^^^^^^^^^^^^^^^^^^^^^^^^^^^^^^^^^^^^^^^^^^^^^^^^^^
  File "/usr/lib/python3/dist-packages/pigpio.py", line 2874, in i2c_read_byte_data
    return _u2i(_pigpio_command(self.sl, _PI_CMD_I2CRB, handle, reg))
           ^^^^^^^^^^^^^^^^^^^^^^^^^^^^^^^^^^^^^^^^^^^^^^^^^^^^^^^^^^
  File "/usr/lib/python3/dist-packages/pigpio.py", line 1011, in _u2i
    raise error(error_text(v))
pigpio.error: 'I2C read failed'


[2025-07-14 23:31:44]
Git repositories synchronized
	

	NoneType: None


[2025-07-14 23:31:44]
Terminating programm
	

	NoneType: None


New initialisation demanded at: 2025-07-15 01:26:41

Running in version 1.2

New initialisation demanded at: 2025-07-15 08:14:50

Running in version 1.2

[2025-07-15 23:31:17]
Git repositories synchronized
	

	NoneType: None


[2025-07-15 23:31:17]
Terminating programm
	

	NoneType: None


New initialisation demanded at: 2025-07-16 01:31:40

Running in version 1.2

[2025-07-16 20:33:08]
Error 1 at reading or storing sensor data.
	'I2C read failed'

	Traceback (most recent call last):
  File "/home/raspi/CO2_Project/main.py", line 211, in <module>
    g_co2_sensor.read_all()
  File "/home/raspi/CO2_Project/ccs811LIBRARY.py", line 191, in read_all
    if self.data_available():
       ^^^^^^^^^^^^^^^^^^^^^
  File "/home/raspi/CO2_Project/ccs811LIBRARY.py", line 172, in data_available
    value = self.pi.i2c_read_byte_data(self.device, CSS811_STATUS)
            ^^^^^^^^^^^^^^^^^^^^^^^^^^^^^^^^^^^^^^^^^^^^^^^^^^^^^^
  File "/usr/lib/python3/dist-packages/pigpio.py", line 2874, in i2c_read_byte_data
    return _u2i(_pigpio_command(self.sl, _PI_CMD_I2CRB, handle, reg))
           ^^^^^^^^^^^^^^^^^^^^^^^^^^^^^^^^^^^^^^^^^^^^^^^^^^^^^^^^^^
  File "/usr/lib/python3/dist-packages/pigpio.py", line 1011, in _u2i
    raise error(error_text(v))
pigpio.error: 'I2C read failed'


[2025-07-16 23:31:17]
Git repositories synchronized
	

	NoneType: None


[2025-07-16 23:31:17]
Terminating programm
	

	NoneType: None


New initialisation demanded at: 2025-07-17 01:31:28

Running in version 1.2

